Crashed on this line:
[6/27/12 4:56:45 PM] Nick: We're getting general feedback from the cutoff reminder emails. Â Looks like it's successful for Friday's cutoffs.

With this error:
Traceback (most recent call last):
  File "./StackBot.py", line 97, in <module>
    main()
  File "./StackBot.py", line 94, in main
    bot.start()
  File "/usr/local/lib/python2.7/dist-packages/irc/bot.py", line 240, in start
    super(SingleServerIRCBot, self).start()
  File "/usr/local/lib/python2.7/dist-packages/irc/client.py", line 1209, in start
    self.ircobj.process_forever()
  File "/usr/local/lib/python2.7/dist-packages/irc/client.py", line 253, in process_forever
    self.process_once(timeout)
  File "/usr/local/lib/python2.7/dist-packages/irc/client.py", line 238, in process_once
    self.process_data(i)
  File "/usr/local/lib/python2.7/dist-packages/irc/client.py", line 206, in process_data
    c.process_data()
  File "/usr/local/lib/python2.7/dist-packages/irc/client.py", line 677, in process_data
    self._handle_event(Event(command, NickMask(prefix), target, [m]))
  File "/usr/local/lib/python2.7/dist-packages/irc/client.py", line 699, in _handle_event
    self.irclibobj._handle_event(self, event)
  File "/usr/local/lib/python2.7/dist-packages/irc/client.py", line 360, in _handle_event
    if handler[1](connection, event) == "NO MORE":
  File "/usr/local/lib/python2.7/dist-packages/irc/client.py", line 1144, in _dispatcher
    getattr(self, m)(c, e)
  File "./StackBot.py", line 39, in on_pubmsg
    if self.nickname in arguments or 'stack' in arguments:
UnicodeDecodeError: 'ascii' codec can't decode byte 0xc2 in position 91: ordinal not in range(128)

